<mujoco model="urdf_robot">
  <option iterations="50" timestep="0.001" solver="PGS" gravity="0 0 -9.81" />

  <compiler angle="radian" meshdir="meshes" eulerseq="zyx" autolimits="true" />

  <default>
    <joint limited="true" damping="0.01" armature="0.01" frictionloss="0.01" />
    <geom condim="4" contype="1" conaffinity="15" friction="0.9 0.2 0.2" solref="0.001 2" />
    <motor ctrllimited="true" />
    <equality solref="0.001 2" />
    <default class="visualgeom">
      <geom material="visualgeom" condim="1" contype="0" conaffinity="0" />
    </default>
  </default>

  <asset>
    <mesh name="Torso_-_Middle_Section_p1" file="Torso_-_Middle_Section_p1.stl" />
    <mesh name="LHS,_FRONT" file="LHS,_FRONT.stl" />
    <mesh name="RHS,_FRONT" file="RHS,_FRONT.stl" />
    <mesh name="Rear_Right_Servo_Box" file="Rear_Right_Servo_Box.stl" />
    <mesh name="LHS,_REAR" file="LHS,_REAR.stl" />
    <mesh name="Hip_Horn" file="Hip_Horn.stl" />
    <mesh name="Knee_Horn" file="Knee_Horn.stl" />
    <mesh name="Hip_Horn_2" file="Hip_Horn_2.stl" />
    <mesh name="Knee_Horn_2" file="Knee_Horn_2.stl" />
    <mesh name="Hip_Horn_3" file="Hip_Horn_3.stl" />
    <mesh name="Knee_Horn_3" file="Knee_Horn_3.stl" />
    <mesh name="Knee_Horn_4" file="Knee_Horn_4.stl" />
    <mesh name="Hip_Horn_4" file="Hip_Horn_4.stl" />
    <mesh name="LHS,_Servo_Cam_-_NEW" file="LHS,_Servo_Cam_-_NEW.stl" />
    <mesh name="Push_Rod,_Cam" file="Push_Rod,_Cam.stl" />
    <mesh name="RHS,_Servo_Cam" file="RHS,_Servo_Cam.stl" />
    <mesh name="Push_Rod,_Cam_2" file="Push_Rod,_Cam_2.stl" />
    <mesh name="RHS,_Servo_Cam_2" file="RHS,_Servo_Cam_2.stl" />
    <mesh name="Push_Rod,_Cam_3" file="Push_Rod,_Cam_3.stl" />
    <mesh name="LHS,_Servo_Cam_-_NEW_2" file="LHS,_Servo_Cam_-_NEW_2.stl" />
    <mesh name="(RIGHT_Lower_Leg_simple)-(Boss-Extrude3)" file="(RIGHT_Lower_Leg_simple)-(Boss-Extrude3).stl" />
    <mesh name="(RIGHT_Lower_Leg_simple)-(Boss-Extrude3)_2" file="(RIGHT_Lower_Leg_simple)-(Boss-Extrude3)_2.stl" />
    <mesh name="(RIGHT_Lower_Leg_simple)-(Boss-Extrude3)_3" file="(RIGHT_Lower_Leg_simple)-(Boss-Extrude3)_3.stl" />
    <mesh name="(RIGHT_Lower_Leg_simple)-(Boss-Extrude3)_4" file="(RIGHT_Lower_Leg_simple)-(Boss-Extrude3)_4.stl" />
    <mesh name="Push_Rod,_Cam_4" file="Push_Rod,_Cam_4.stl" />
    <mesh name="Push_Rod,_Upper" file="Push_Rod,_Upper.stl" />
    <mesh name="Push_Rod,_Upper_2" file="Push_Rod,_Upper_2.stl" />
    <mesh name="Push_Rod,_Upper_3" file="Push_Rod,_Upper_3.stl" />
    <mesh name="Push_Rod,_Upper_4" file="Push_Rod,_Upper_4.stl" />
    <texture name="texplane" type="2d" builtin="checker" rgb1=".0 .0 .0" rgb2=".8 .8 .8" width="100" height="100" />
    <material name="matplane" reflectance="0." texture="texplane" texrepeat="1 1" texuniform="true" />
    <material name="visualgeom" rgba="0.5 0.9 0.2 1" />
  </asset>

  <worldbody>
    <light directional="true" diffuse="0.4 0.4 0.4" specular="0.1 0.1 0.1" pos="0 0 5.0" dir="0 0 -1" castshadow="false" />
    <light directional="true" diffuse="0.6 0.6 0.6" specular="0.2 0.2 0.2" pos="0 0 4" dir="0 0 -1" />
    <geom name="ground" type="plane" pos="0 0 0" size="100 100 0.001" quat="1 0 0 0" material="matplane" condim="3" conaffinity="15" />
    <camera name="fixed" pos="0 -3.0 0.5" xyaxes="1 0 0 0 0 1" />
    <camera name="track" mode="trackcom" pos="0 -3.0 0.5" xyaxes="1 0 0 0 0 1" />
    <body name="root" pos="0 0 0.01" quat="1 0 0 0">
      <freejoint name="root" />
      <site name="imu" size="0.01" pos="0 0 0" />
      <geom type="mesh" rgba="0.682353 0.333333 0.737255 1" mesh="Torso_-_Middle_Section_p1" contype="1" conaffinity="0" density="0" group="1" class="visualgeom" />
      <geom type="mesh" rgba="0.682353 0.333333 0.737255 1" mesh="Torso_-_Middle_Section_p1" />
      <body name="LHS,_FRONT" pos="0.0528396 -0.0797826 0.00621881" quat="0.707107 -0.707107 2.28709e-08 -1.50228e-08">
        <inertial pos="3.00389e-07 -0.00707888 -0.0385084" quat="0.501247 0.498509 0.513412 0.486465" mass="0.553078" diaginertia="0.000232539 0.0002139 0.000171814" />
        <joint name="dof_shoulder_front_left" pos="0 0 0" axis="0 0 1" range="0 3.14159" actuatorfrcrange="-80 80" />
        <geom type="mesh" rgba="0.972549 0.529412 0.00392157 1" mesh="LHS,_FRONT" contype="1" conaffinity="0" density="0" group="1" class="visualgeom" />
        <geom type="mesh" rgba="0.972549 0.529412 0.00392157 1" mesh="LHS,_FRONT" />
        <body name="Hip_Horn" pos="-0.0145 -0.03185 -0.02865" quat="0.5 -0.5 -0.5 -0.5">
          <inertial pos="0.0349472 0.0349472 -0.0140663" quat="-0.264282 0.668182 0.27677 0.638033" mass="0.0511315" diaginertia="0.000102532 0.000101158 4.51177e-06" />
          <joint name="Revolute_1" pos="0 0 0" axis="0 0 1" limited="false" actuatorfrcrange="-80 80" />
          <geom type="mesh" rgba="0.615686 0.811765 0.929412 1" mesh="Hip_Horn" contype="1" conaffinity="0" density="0" group="1" class="visualgeom" />
          <geom type="mesh" rgba="0.615686 0.811765 0.929412 1" mesh="Hip_Horn" />
          <body name="LHS,_Servo_Cam_-_NEW" pos="0 0 -0.00315" quat="0.707107 0 0 -0.707107">
            <inertial pos="0.00181979 -0.0191473 -0.0015295" quat="0 0.707107 0 0.707107" mass="0.0214782" diaginertia="1.28908e-05 7.75454e-06 5.36417e-06" />
            <joint name="Revolute_4" pos="0 0 0" axis="0 0 1" limited="false" actuatorfrcrange="-80 80" />
            <geom type="mesh" rgba="0.909804 0.572549 0.164706 1" mesh="LHS,_Servo_Cam_-_NEW" contype="1" conaffinity="0" density="0" group="1" class="visualgeom" />
            <geom type="mesh" rgba="0.909804 0.572549 0.164706 1" mesh="LHS,_Servo_Cam_-_NEW" />
          </body>
          <body name="(RIGHT_Lower_Leg_simple)-(Boss-Extrude3)" pos="0.0919239 0.0919239 -0.0132" quat="8.88021e-09 -0.382683 0.92388 -2.14387e-08">
            <inertial pos="0.0449127 0.0431117 0.00218961" quat="0.246713 0.300886 0.630225 0.671876" mass="0.0576445" diaginertia="0.000157192 0.000156187 5.83259e-06" />
            <joint name="Revolute_5" pos="0 0 0" axis="0 0 1" limited="false" actuatorfrcrange="-80 80" />
            <geom type="mesh" rgba="0.372549 0.654902 0.239216 1" mesh="(RIGHT_Lower_Leg_simple)-(Boss-Extrude3)" contype="1" conaffinity="0" density="0" group="1" class="visualgeom" />
            <geom type="mesh" rgba="0.372549 0.654902 0.239216 1" mesh="(RIGHT_Lower_Leg_simple)-(Boss-Extrude3)" />
            <body name="Push_Rod,_Upper_2" pos="-0.0282815 -0.0238569 -0.00405" quat="-2.32051e-08 1 0 0">
              <inertial pos="0.0651405 0 -0.0020636" quat="0 0.707107 0 0.707107" mass="0.00677755" diaginertia="1.01233e-05 1.00822e-05 1e-06" />
              <joint name="Revolute_6" pos="0 0 0" axis="0 0 1" limited="false" actuatorfrcrange="-80 80" />
              <geom type="mesh" rgba="0.282353 0.54902 0.160784 1" mesh="Push_Rod,_Upper_2" contype="1" conaffinity="0" density="0" group="1" class="visualgeom" />
              <geom type="mesh" rgba="0.282353 0.54902 0.160784 1" mesh="Push_Rod,_Upper_2" />
            </body>
          </body>
        </body>
        <body name="Knee_Horn" pos="0.0145 -0.03185 -0.04865" quat="-1.64085e-08 1.64085e-08 -0.707107 -0.707107">
          <inertial pos="0 -0.0103855 -0.00111939" mass="0.00385987" diaginertia="1e-06 1e-06 1e-06" />
          <joint name="Revolute_2" pos="0 0 0" axis="0 0 1" limited="false" actuatorfrcrange="-80 80" />
          <geom type="mesh" rgba="0.615686 0.811765 0.929412 1" mesh="Knee_Horn" contype="1" conaffinity="0" density="0" group="1" class="visualgeom" />
          <geom type="mesh" rgba="0.615686 0.811765 0.929412 1" mesh="Knee_Horn" />
          <body name="Push_Rod,_Cam" pos="0 -0.035 -0.00705">
            <inertial pos="0.0188243 0 -0.00182735" mass="0.00204623" diaginertia="1e-06 1e-06 1e-06" />
            <joint name="Revolute_3_3" pos="0 0 0" axis="0 0 1" limited="false" actuatorfrcrange="-80 80" />
            <geom type="mesh" rgba="0.654902 0.823529 0.576471 1" mesh="Push_Rod,_Cam" contype="1" conaffinity="0" density="0" group="1" class="visualgeom" />
            <geom type="mesh" rgba="0.654902 0.823529 0.576471 1" mesh="Push_Rod,_Cam" />
          </body>
        </body>
      </body>
      <body name="RHS,_FRONT" pos="-0.0526604 -0.0797826 0.00621881" quat="4.18177e-08 -3.92402e-09 0.707107 0.707107">
        <inertial pos="-3.37274e-07 -0.0070789 -0.0385084" quat="0.513408 0.486468 0.501245 0.498513" mass="0.553077" diaginertia="0.000232538 0.000213899 0.000171813" />
        <joint name="dof_shoulder_front_right" pos="0 0 0" axis="0 0 1" range="0 3.14159" actuatorfrcrange="-80 80" />
        <geom type="mesh" rgba="0.972549 0.529412 0.00392157 1" mesh="RHS,_FRONT" contype="1" conaffinity="0" density="0" group="1" class="visualgeom" />
        <geom type="mesh" rgba="0.972549 0.529412 0.00392157 1" mesh="RHS,_FRONT" />
        <body name="Hip_Horn_2" pos="0.0145 -0.03185 -0.02865" quat="0.707107 -0.707107 0 -3.2817e-08">
          <inertial pos="-0.0349472 -0.0349472 -0.0140663" quat="-0.27677 0.638033 0.264282 0.668182" mass="0.0511315" diaginertia="0.000102532 0.000101158 4.51177e-06" />
          <joint name="Revolute_3" pos="0 0 0" axis="0 0 1" limited="false" actuatorfrcrange="-80 80" />
          <geom type="mesh" rgba="0.615686 0.811765 0.929412 1" mesh="Hip_Horn_2" contype="1" conaffinity="0" density="0" group="1" class="visualgeom" />
          <geom type="mesh" rgba="0.615686 0.811765 0.929412 1" mesh="Hip_Horn_2" />
          <body name="RHS,_Servo_Cam" pos="0 0 -0.00315" quat="0.707107 0 0 0.707107">
            <inertial pos="-0.00181979 -0.0191473 -0.0015295" quat="0 0.707107 0 0.707107" mass="0.0214782" diaginertia="1.28908e-05 7.75454e-06 5.36417e-06" />
            <joint name="Revolute_4_2" pos="0 0 0" axis="0 0 1" limited="false" actuatorfrcrange="-80 80" />
            <geom type="mesh" rgba="0.909804 0.572549 0.164706 1" mesh="RHS,_Servo_Cam" contype="1" conaffinity="0" density="0" group="1" class="visualgeom" />
            <geom type="mesh" rgba="0.909804 0.572549 0.164706 1" mesh="RHS,_Servo_Cam" />
          </body>
          <body name="(RIGHT_Lower_Leg_simple)-(Boss-Extrude3)_2" pos="-0.0919239 -0.0919239 -0.0132" quat="2.14387e-08 -0.92388 -0.382683 8.88021e-09">
            <inertial pos="0.0449127 -0.0431117 0.00218961" quat="0.671876 0.630225 0.300886 0.246713" mass="0.0576445" diaginertia="0.000157192 0.000156187 5.83259e-06" />
            <joint name="Revolute_5_2" pos="0 0 0" axis="0 0 1" limited="false" actuatorfrcrange="-80 80" />
            <geom type="mesh" rgba="0.372549 0.654902 0.239216 1" mesh="(RIGHT_Lower_Leg_simple)-(Boss-Extrude3)_2" contype="1" conaffinity="0" density="0" group="1" class="visualgeom" />
            <geom type="mesh" rgba="0.372549 0.654902 0.239216 1" mesh="(RIGHT_Lower_Leg_simple)-(Boss-Extrude3)_2" />
            <body name="Push_Rod,_Upper_3" pos="-0.0282815 0.0238569 -0.00405" quat="-2.32051e-08 1 0 0">
              <inertial pos="0.0651405 0 -0.0020636" quat="0 0.707107 0 0.707107" mass="0.00677755" diaginertia="1.01233e-05 1.00822e-05 1e-06" />
              <joint name="Revolute_6_2" pos="0 0 0" axis="0 0 1" limited="false" actuatorfrcrange="-80 80" />
              <geom type="mesh" rgba="0.282353 0.54902 0.160784 1" mesh="Push_Rod,_Upper_3" contype="1" conaffinity="0" density="0" group="1" class="visualgeom" />
              <geom type="mesh" rgba="0.282353 0.54902 0.160784 1" mesh="Push_Rod,_Upper_3" />
            </body>
          </body>
        </body>
        <body name="Knee_Horn_2" pos="-0.0145 -0.03185 -0.04865" quat="0.5 -0.5 0.5 0.5">
          <inertial pos="0 -0.0103855 -0.00111939" mass="0.00385987" diaginertia="1e-06 1e-06 1e-06" />
          <joint name="Revolute_1_2" pos="0 0 0" axis="0 0 1" range="0.523599 2.44346" limited="false" actuatorfrcrange="-80 80" />
          <geom type="mesh" rgba="0.615686 0.811765 0.929412 1" mesh="Knee_Horn_2" contype="1" conaffinity="0" density="0" group="1" class="visualgeom" />
          <geom type="mesh" rgba="0.615686 0.811765 0.929412 1" mesh="Knee_Horn_2" />
          <body name="Push_Rod,_Cam_2" pos="0 -0.035 -0.00705" quat="-2.32051e-08 0 0 1">
            <inertial pos="0.0188243 0 -0.00182735" mass="0.00204623" diaginertia="1e-06 1e-06 1e-06" />
            <joint name="Revolute_2_2" pos="0 0 0" axis="0 0 1" limited="false" actuatorfrcrange="-80 80" />
            <geom type="mesh" rgba="0.654902 0.823529 0.576471 1" mesh="Push_Rod,_Cam_2" contype="1" conaffinity="0" density="0" group="1" class="visualgeom" />
            <geom type="mesh" rgba="0.654902 0.823529 0.576471 1" mesh="Push_Rod,_Cam_2" />
          </body>
        </body>
      </body>
      <body name="Rear_Right_Servo_Box" pos="-0.0526604 0.0798174 0.00621881" quat="0.707107 0.707107 3.92402e-09 -3.92402e-09">
        <inertial pos="-3.32755e-07 0.0070789 -0.0385085" quat="0.486475 0.513421 0.498507 0.50123" mass="0.553077" diaginertia="0.000232538 0.000213899 0.000171813" />
        <joint name="dof_shoulder_rear_right" pos="0 0 0" axis="0 0 1" range="0 3.14159" actuatorfrcrange="-80 80" />
        <geom type="mesh" rgba="0.972549 0.529412 0.00392157 1" mesh="Rear_Right_Servo_Box" contype="1" conaffinity="0" density="0" group="1" class="visualgeom" />
        <geom type="mesh" rgba="0.972549 0.529412 0.00392157 1" mesh="Rear_Right_Servo_Box" />
        <body name="Hip_Horn_3" pos="0.0145 0.03185 -0.04865" quat="0.5 0.5 -0.5 0.5">
          <inertial pos="0.0349472 0.0349472 -0.0140663" quat="-0.264282 0.668182 0.27677 0.638033" mass="0.0511315" diaginertia="0.000102532 0.000101158 4.51177e-06" />
          <joint name="dof_servo_hip" pos="0 0 0" axis="0 0 1" range="0 3.14159" actuatorfrcrange="-80 80" />
          <geom type="mesh" rgba="0.615686 0.811765 0.929412 1" mesh="Hip_Horn_3" contype="1" conaffinity="0" density="0" group="1" class="visualgeom" />
          <geom type="mesh" rgba="0.615686 0.811765 0.929412 1" mesh="Hip_Horn_3" />
          <body name="RHS,_Servo_Cam_2" pos="0 0 -0.00315">
            <inertial pos="-0.00181979 -0.0191473 -0.0015295" quat="0 0.707107 0 0.707107" mass="0.0214782" diaginertia="1.28908e-05 7.75454e-06 5.36417e-06" />
            <joint name="dof_hip_cam__continuous" pos="0 0 0" axis="0 0 1" limited="false" actuatorfrcrange="-80 80" />
            <geom type="mesh" rgba="0.909804 0.572549 0.164706 1" mesh="RHS,_Servo_Cam_2" contype="1" conaffinity="0" density="0" group="1" class="visualgeom" />
            <geom type="mesh" rgba="0.909804 0.572549 0.164706 1" mesh="RHS,_Servo_Cam_2" />
          </body>
          <body name="(RIGHT_Lower_Leg_simple)-(Boss-Extrude3)_3" pos="0.0919239 0.0919239 -0.0132" quat="2.14387e-08 -0.92388 -0.382683 8.88021e-09">
            <inertial pos="0.0449127 -0.0431117 0.00218961" quat="0.671876 0.630225 0.300886 0.246713" mass="0.0576445" diaginertia="0.000157192 0.000156187 5.83259e-06" />
            <joint name="dof_knee__continuous" pos="0 0 0" axis="0 0 1" limited="false" actuatorfrcrange="-80 80" />
            <geom type="mesh" rgba="0.372549 0.654902 0.239216 1" mesh="(RIGHT_Lower_Leg_simple)-(Boss-Extrude3)_3" contype="1" conaffinity="0" density="0" group="1" class="visualgeom" />
            <geom type="mesh" rgba="0.372549 0.654902 0.239216 1" mesh="(RIGHT_Lower_Leg_simple)-(Boss-Extrude3)_3" />
            <body name="Push_Rod,_Upper_4" pos="-0.0282815 0.0238569 -0.00405" quat="-1.64085e-08 0.707107 -0.707107 1.64085e-08">
              <inertial pos="-0.0650595 0 -0.0020636" quat="0 0.707107 0 0.707107" mass="0.00677755" diaginertia="1.01233e-05 1.00822e-05 1e-06" />
              <joint name="dof_linkage_1_continuous" pos="0 0 0" axis="0 0 1" limited="false" actuatorfrcrange="-80 80" />
              <geom type="mesh" rgba="0.282353 0.54902 0.160784 1" mesh="Push_Rod,_Upper_4" contype="1" conaffinity="0" density="0" group="1" class="visualgeom" />
              <geom type="mesh" rgba="0.282353 0.54902 0.160784 1" mesh="Push_Rod,_Upper_4" />
            </body>
          </body>
        </body>
        <body name="Knee_Horn_3" pos="-0.0145 0.03185 -0.02865" quat="0.5 0.5 -0.5 0.5">
          <inertial pos="0 -0.0103855 -0.00111939" mass="0.00385987" diaginertia="1e-06 1e-06 1e-06" />
          <joint name="dof_servo_knee" pos="0 0 0" axis="0 0 1" range="0 3.14159" actuatorfrcrange="-80 80" />
          <geom type="mesh" rgba="0.615686 0.811765 0.929412 1" mesh="Knee_Horn_3" contype="1" conaffinity="0" density="0" group="1" class="visualgeom" />
          <geom type="mesh" rgba="0.615686 0.811765 0.929412 1" mesh="Knee_Horn_3" />
          <body name="Push_Rod,_Cam_3" pos="0 -0.035 -0.00705">
            <inertial pos="0.0188243 0 -0.00182735" mass="0.00204623" diaginertia="1e-06 1e-06 1e-06" />
            <joint name="dof_linkage_2__continuous" pos="0 0 0" axis="0 0 1" limited="false" actuatorfrcrange="-80 80" />
            <geom type="mesh" rgba="0.654902 0.823529 0.576471 1" mesh="Push_Rod,_Cam_3" contype="1" conaffinity="0" density="0" group="1" class="visualgeom" />
            <geom type="mesh" rgba="0.654902 0.823529 0.576471 1" mesh="Push_Rod,_Cam_3" />
          </body>
        </body>
      </body>
      <body name="LHS,_REAR" pos="0.0528396 0.0798174 0.00621881" quat="-2.28709e-08 -2.28709e-08 -0.707107 0.707107">
        <inertial pos="3.36557e-07 0.0070789 -0.0385084" quat="0.498505 0.501232 0.486474 0.513423" mass="0.553077" diaginertia="0.000232538 0.000213899 0.000171813" />
        <joint name="dof_shoulder_rear_left" pos="0 0 0" axis="0 0 1" range="0 3.14159" actuatorfrcrange="-80 80" />
        <geom type="mesh" rgba="0.972549 0.529412 0.00392157 1" mesh="LHS,_REAR" contype="1" conaffinity="0" density="0" group="1" class="visualgeom" />
        <geom type="mesh" rgba="0.972549 0.529412 0.00392157 1" mesh="LHS,_REAR" />
        <body name="Knee_Horn_4" pos="0.0145 0.03185 -0.02865" quat="-1.64085e-08 -1.64085e-08 0.707107 -0.707107">
          <inertial pos="0 -0.0103855 -0.00111939" mass="0.00385987" diaginertia="1e-06 1e-06 1e-06" />
          <joint name="Revolute_1_3" pos="0 0 0" axis="0 0 1" limited="false" actuatorfrcrange="-80 80" />
          <geom type="mesh" rgba="0.615686 0.811765 0.929412 1" mesh="Knee_Horn_4" contype="1" conaffinity="0" density="0" group="1" class="visualgeom" />
          <geom type="mesh" rgba="0.615686 0.811765 0.929412 1" mesh="Knee_Horn_4" />
        </body>
        <body name="Hip_Horn_4" pos="-0.0145 0.03185 -0.04865" quat="0.707107 0.707107 3.2817e-08 0">
          <inertial pos="0.0349472 -0.0349472 -0.0140663" quat="0.264282 0.668182 -0.27677 0.638033" mass="0.0511315" diaginertia="0.000102532 0.000101158 4.51177e-06" />
          <joint name="Revolute_3_2" pos="0 0 0" axis="0 0 1" limited="false" actuatorfrcrange="-80 80" />
          <geom type="mesh" rgba="0.615686 0.811765 0.929412 1" mesh="Hip_Horn_4" contype="1" conaffinity="0" density="0" group="1" class="visualgeom" />
          <geom type="mesh" rgba="0.615686 0.811765 0.929412 1" mesh="Hip_Horn_4" />
          <body name="LHS,_Servo_Cam_-_NEW_2" pos="0 0 -0.00315" quat="-2.32051e-08 0 0 1">
            <inertial pos="0.00181979 -0.0191473 -0.0015295" quat="0 0.707107 0 0.707107" mass="0.0214782" diaginertia="1.28908e-05 7.75454e-06 5.36417e-06" />
            <joint name="Revolute_4_3" pos="0 0 0" axis="0 0 1" limited="false" actuatorfrcrange="-80 80" />
            <geom type="mesh" rgba="0.909804 0.572549 0.164706 1" mesh="LHS,_Servo_Cam_-_NEW_2" contype="1" conaffinity="0" density="0" group="1" class="visualgeom" />
            <geom type="mesh" rgba="0.909804 0.572549 0.164706 1" mesh="LHS,_Servo_Cam_-_NEW_2" />
            <body name="Push_Rod,_Cam_4" pos="-0.0335364 -0.0268812 -0.0039" quat="0.707107 0 0 -0.707107">
              <inertial pos="-0.0187757 0 -0.00182735" mass="0.00204623" diaginertia="1e-06 1e-06 1e-06" />
              <joint name="dof_four_bar_top_2" pos="0 0 0" axis="0 0 1" limited="false" actuatorfrcrange="-80 80" />
              <geom type="mesh" rgba="0.654902 0.823529 0.576471 1" mesh="Push_Rod,_Cam_4" contype="1" conaffinity="0" density="0" group="1" class="visualgeom" />
              <geom type="mesh" rgba="0.654902 0.823529 0.576471 1" mesh="Push_Rod,_Cam_4" />
            </body>
            <body name="Push_Rod,_Upper" pos="0.0335364 -0.0268812 -0.006" quat="0.707107 0 0 0.707107">
              <inertial pos="-0.0650595 0 -0.0020636" quat="0 0.707107 0 0.707107" mass="0.00677755" diaginertia="1.01233e-05 1.00822e-05 1e-06" />
              <joint name="dof_four_bar_top_1" pos="0 0 0" axis="0 0 1" limited="false" actuatorfrcrange="-80 80" />
              <geom type="mesh" rgba="0.282353 0.54902 0.160784 1" mesh="Push_Rod,_Upper" contype="1" conaffinity="0" density="0" group="1" class="visualgeom" />
              <geom type="mesh" rgba="0.282353 0.54902 0.160784 1" mesh="Push_Rod,_Upper" />
            </body>
          </body>
          <body name="(RIGHT_Lower_Leg_simple)-(Boss-Extrude3)_4" pos="0.0919239 -0.0919239 -0.0132" quat="2.14387e-08 -0.92388 -0.382683 8.88021e-09">
            <inertial pos="0.0449127 0.0431117 0.00218961" quat="0.246713 0.300886 0.630225 0.671876" mass="0.0576445" diaginertia="0.000157192 0.000156187 5.83259e-06" />
            <joint name="Revolute_7" pos="0 0 0" axis="0 0 1" limited="false" actuatorfrcrange="-80 80" />
            <geom type="mesh" rgba="0.372549 0.654902 0.239216 1" mesh="(RIGHT_Lower_Leg_simple)-(Boss-Extrude3)_4" contype="1" conaffinity="0" density="0" group="1" class="visualgeom" />
            <geom type="mesh" rgba="0.372549 0.654902 0.239216 1" mesh="(RIGHT_Lower_Leg_simple)-(Boss-Extrude3)_4" />
          </body>
        </body>
      </body>
    </body>
  </worldbody>

  <equality>
    <connect body1="Push_Rod,_Upper" body2="RHS,_Servo_Cam" anchor="0.0651405 0 -0.0020636"/>
  </equality>

  <actuator>
    <motor name="dof_shoulder_front_left" joint="dof_shoulder_front_left" ctrllimited="true" ctrlrange="-80 80" gear="1" />
    <motor name="Revolute_1" joint="Revolute_1" ctrllimited="true" ctrlrange="-80 80" gear="1" />
    <motor name="Revolute_4" joint="Revolute_4" ctrllimited="true" ctrlrange="-80 80" gear="1" />
    <motor name="Revolute_5" joint="Revolute_5" ctrllimited="true" ctrlrange="-80 80" gear="1" />
    <motor name="Revolute_6" joint="Revolute_6" ctrllimited="true" ctrlrange="-80 80" gear="1" />
    <motor name="Revolute_2" joint="Revolute_2" ctrllimited="true" ctrlrange="-80 80" gear="1" />
    <motor name="Revolute_3_3" joint="Revolute_3_3" ctrllimited="true" ctrlrange="-80 80" gear="1" />
    <motor name="dof_shoulder_front_right" joint="dof_shoulder_front_right" ctrllimited="true" ctrlrange="-80 80" gear="1" />
    <motor name="Revolute_3" joint="Revolute_3" ctrllimited="true" ctrlrange="-80 80" gear="1" />
    <motor name="Revolute_4_2" joint="Revolute_4_2" ctrllimited="true" ctrlrange="-80 80" gear="1" />
    <motor name="Revolute_5_2" joint="Revolute_5_2" ctrllimited="true" ctrlrange="-80 80" gear="1" />
    <motor name="Revolute_6_2" joint="Revolute_6_2" ctrllimited="true" ctrlrange="-80 80" gear="1" />
    <motor name="Revolute_1_2" joint="Revolute_1_2" ctrllimited="true" ctrlrange="-80 80" gear="1" />
    <motor name="Revolute_2_2" joint="Revolute_2_2" ctrllimited="true" ctrlrange="-80 80" gear="1" />
    <motor name="dof_shoulder_rear_right" joint="dof_shoulder_rear_right" ctrllimited="true" ctrlrange="-80 80" gear="1" />
    <motor name="dof_servo_hip" joint="dof_servo_hip" ctrllimited="true" ctrlrange="-80 80" gear="1" />
    <motor name="dof_hip_cam__continuous" joint="dof_hip_cam__continuous" ctrllimited="true" ctrlrange="-80 80" gear="1" />
    <motor name="dof_knee__continuous" joint="dof_knee__continuous" ctrllimited="true" ctrlrange="-80 80" gear="1" />
    <motor name="dof_linkage_1_continuous" joint="dof_linkage_1_continuous" ctrllimited="true" ctrlrange="-80 80" gear="1" />
    <motor name="dof_servo_knee" joint="dof_servo_knee" ctrllimited="true" ctrlrange="-80 80" gear="1" />
    <motor name="dof_linkage_2__continuous" joint="dof_linkage_2__continuous" ctrllimited="true" ctrlrange="-80 80" gear="1" />
    <motor name="dof_shoulder_rear_left" joint="dof_shoulder_rear_left" ctrllimited="true" ctrlrange="-80 80" gear="1" />
    <motor name="Revolute_1_3" joint="Revolute_1_3" ctrllimited="true" ctrlrange="-80 80" gear="1" />
    <motor name="Revolute_3_2" joint="Revolute_3_2" ctrllimited="true" ctrlrange="-80 80" gear="1" />
    <motor name="Revolute_4_3" joint="Revolute_4_3" ctrllimited="true" ctrlrange="-80 80" gear="1" />
<motor name="Revolute_7" joint="Revolute_7" ctrllimited="true" ctrlrange="-80 80" gear="1" />
  </actuator>

  <sensor>
    <actuatorpos name="dof_shoulder_front_left_p" actuator="dof_shoulder_front_left" />
    <actuatorvel name="dof_shoulder_front_left_v" actuator="dof_shoulder_front_left" />
    <actuatorfrc name="dof_shoulder_front_left_f" actuator="dof_shoulder_front_left" noise="0.001" />
    <actuatorpos name="Revolute_1_p" actuator="Revolute_1" />
    <actuatorvel name="Revolute_1_v" actuator="Revolute_1" />
    <actuatorfrc name="Revolute_1_f" actuator="Revolute_1" noise="0.001" />
    <actuatorpos name="Revolute_4_p" actuator="Revolute_4" />
    <actuatorvel name="Revolute_4_v" actuator="Revolute_4" />
    <actuatorfrc name="Revolute_4_f" actuator="Revolute_4" noise="0.001" />
    <actuatorpos name="Revolute_5_p" actuator="Revolute_5" />
    <actuatorvel name="Revolute_5_v" actuator="Revolute_5" />
    <actuatorfrc name="Revolute_5_f" actuator="Revolute_5" noise="0.001" />
    <actuatorpos name="Revolute_6_p" actuator="Revolute_6" />
    <actuatorvel name="Revolute_6_v" actuator="Revolute_6" />
    <actuatorfrc name="Revolute_6_f" actuator="Revolute_6" noise="0.001" />
    <actuatorpos name="Revolute_2_p" actuator="Revolute_2" />
    <actuatorvel name="Revolute_2_v" actuator="Revolute_2" />
    <actuatorfrc name="Revolute_2_f" actuator="Revolute_2" noise="0.001" />
    <actuatorpos name="Revolute_3_3_p" actuator="Revolute_3_3" />
    <actuatorvel name="Revolute_3_3_v" actuator="Revolute_3_3" />
    <actuatorfrc name="Revolute_3_3_f" actuator="Revolute_3_3" noise="0.001" />
    <actuatorpos name="dof_shoulder_front_right_p" actuator="dof_shoulder_front_right" />
    <actuatorvel name="dof_shoulder_front_right_v" actuator="dof_shoulder_front_right" />
    <actuatorfrc name="dof_shoulder_front_right_f" actuator="dof_shoulder_front_right" noise="0.001" />
    <actuatorpos name="Revolute_3_p" actuator="Revolute_3" />
    <actuatorvel name="Revolute_3_v" actuator="Revolute_3" />
    <actuatorfrc name="Revolute_3_f" actuator="Revolute_3" noise="0.001" />
    <actuatorpos name="Revolute_4_2_p" actuator="Revolute_4_2" />
    <actuatorvel name="Revolute_4_2_v" actuator="Revolute_4_2" />
    <actuatorfrc name="Revolute_4_2_f" actuator="Revolute_4_2" noise="0.001" />
    <actuatorpos name="Revolute_5_2_p" actuator="Revolute_5_2" />
    <actuatorvel name="Revolute_5_2_v" actuator="Revolute_5_2" />
    <actuatorfrc name="Revolute_5_2_f" actuator="Revolute_5_2" noise="0.001" />
    <actuatorpos name="Revolute_6_2_p" actuator="Revolute_6_2" />
    <actuatorvel name="Revolute_6_2_v" actuator="Revolute_6_2" />
    <actuatorfrc name="Revolute_6_2_f" actuator="Revolute_6_2" noise="0.001" />
    <actuatorpos name="Revolute_1_2_p" actuator="Revolute_1_2" />
    <actuatorvel name="Revolute_1_2_v" actuator="Revolute_1_2" />
    <actuatorfrc name="Revolute_1_2_f" actuator="Revolute_1_2" noise="0.001" />
    <actuatorpos name="Revolute_2_2_p" actuator="Revolute_2_2" />
    <actuatorvel name="Revolute_2_2_v" actuator="Revolute_2_2" />
    <actuatorfrc name="Revolute_2_2_f" actuator="Revolute_2_2" noise="0.001" />
    <actuatorpos name="dof_shoulder_rear_right_p" actuator="dof_shoulder_rear_right" />
    <actuatorvel name="dof_shoulder_rear_right_v" actuator="dof_shoulder_rear_right" />
    <actuatorfrc name="dof_shoulder_rear_right_f" actuator="dof_shoulder_rear_right" noise="0.001" />
    <actuatorpos name="dof_servo_hip_p" actuator="dof_servo_hip" />
    <actuatorvel name="dof_servo_hip_v" actuator="dof_servo_hip" />
    <actuatorfrc name="dof_servo_hip_f" actuator="dof_servo_hip" noise="0.001" />
    <actuatorpos name="dof_hip_cam__continuous_p" actuator="dof_hip_cam__continuous" />
    <actuatorvel name="dof_hip_cam__continuous_v" actuator="dof_hip_cam__continuous" />
    <actuatorfrc name="dof_hip_cam__continuous_f" actuator="dof_hip_cam__continuous" noise="0.001" />
    <actuatorpos name="dof_knee__continuous_p" actuator="dof_knee__continuous" />
    <actuatorvel name="dof_knee__continuous_v" actuator="dof_knee__continuous" />
    <actuatorfrc name="dof_knee__continuous_f" actuator="dof_knee__continuous" noise="0.001" />
    <actuatorpos name="dof_linkage_1_continuous_p" actuator="dof_linkage_1_continuous" />
    <actuatorvel name="dof_linkage_1_continuous_v" actuator="dof_linkage_1_continuous" />
    <actuatorfrc name="dof_linkage_1_continuous_f" actuator="dof_linkage_1_continuous" noise="0.001" />
    <actuatorpos name="dof_servo_knee_p" actuator="dof_servo_knee" />
    <actuatorvel name="dof_servo_knee_v" actuator="dof_servo_knee" />
    <actuatorfrc name="dof_servo_knee_f" actuator="dof_servo_knee" noise="0.001" />
    <actuatorpos name="dof_linkage_2__continuous_p" actuator="dof_linkage_2__continuous" />
    <actuatorvel name="dof_linkage_2__continuous_v" actuator="dof_linkage_2__continuous" />
    <actuatorfrc name="dof_linkage_2__continuous_f" actuator="dof_linkage_2__continuous" noise="0.001" />
    <actuatorpos name="dof_shoulder_rear_left_p" actuator="dof_shoulder_rear_left" />
    <actuatorvel name="dof_shoulder_rear_left_v" actuator="dof_shoulder_rear_left" />
    <actuatorfrc name="dof_shoulder_rear_left_f" actuator="dof_shoulder_rear_left" noise="0.001" />
    <actuatorpos name="Revolute_1_3_p" actuator="Revolute_1_3" />
    <actuatorvel name="Revolute_1_3_v" actuator="Revolute_1_3" />
    <actuatorfrc name="Revolute_1_3_f" actuator="Revolute_1_3" noise="0.001" />
    <actuatorpos name="Revolute_3_2_p" actuator="Revolute_3_2" />
    <actuatorvel name="Revolute_3_2_v" actuator="Revolute_3_2" />
    <actuatorfrc name="Revolute_3_2_f" actuator="Revolute_3_2" noise="0.001" />
    <actuatorpos name="Revolute_4_3_p" actuator="Revolute_4_3" />
    <actuatorvel name="Revolute_4_3_v" actuator="Revolute_4_3" />
    <actuatorfrc name="Revolute_4_3_f" actuator="Revolute_4_3" noise="0.001" />
    <actuatorpos name="Revolute_7_p" actuator="Revolute_7" />
    <actuatorvel name="Revolute_7_v" actuator="Revolute_7" />
    <actuatorfrc name="Revolute_7_f" actuator="Revolute_7" noise="0.001" />
    <framequat name="orientation" objtype="site" noise="0.001" objname="imu" />
    <gyro name="angular-velocity" site="imu" noise="0.005" cutoff="34.9" />
  </sensor>
</mujoco>