<mujoco model="front,_right_leg_assy">
  <option iterations="50" timestep="0.001" solver="PGS" gravity="0 0 -9.81" />

  <compiler angle="radian" meshdir="meshes" eulerseq="zyx" autolimits="true" />

  <default>
    <joint limited="true" damping="0.01" armature="0.01" frictionloss="0.01" />
    <geom condim="4" contype="1" conaffinity="15" friction="0.9 0.2 0.2" solref="0.001 2" />
    <motor ctrllimited="true" />
    <equality solref="0.001 2" />
    <default class="visualgeom">
      <geom material="visualgeom" condim="1" contype="0" conaffinity="0" />
    </default>
  </default>

  <asset>
    <mesh name="CLS6336_Servo" file="CLS6336_Servo.stl" />
    <mesh name="Hip_Horn" file="Hip_Horn.stl" />
    <mesh name="RHS,_Servo_Cam" file="RHS,_Servo_Cam.stl" />
    <mesh name="Knee_Horn" file="Knee_Horn.stl" />
    <mesh name="(RIGHT_Lower_Leg_simple)-(Boss-Extrude3)" file="(RIGHT_Lower_Leg_simple)-(Boss-Extrude3).stl" />
    <mesh name="Push_Rod,_Cam" file="Push_Rod,_Cam.stl" />
    <mesh name="Push_Rod,_Upper" file="Push_Rod,_Upper.stl" />
    <texture name="texplane" type="2d" builtin="checker" rgb1=".0 .0 .0" rgb2=".8 .8 .8" width="100" height="100" />
    <material name="matplane" reflectance="0." texture="texplane" texrepeat="1 1" texuniform="true" />
    <material name="visualgeom" rgba="0.5 0.9 0.2 1" />
  </asset>

  <worldbody>
    <light directional="true" diffuse="0.4 0.4 0.4" specular="0.1 0.1 0.1" pos="0 0 5.0" dir="0 0 -1" castshadow="false" />
    <light directional="true" diffuse="0.6 0.6 0.6" specular="0.2 0.2 0.2" pos="0 0 4" dir="0 0 -1" />
    <geom name="ground" type="plane" pos="0 0 0" size="100 100 0.001" quat="1 0 0 0" material="matplane" condim="3" conaffinity="15" />
    <camera name="fixed" pos="0 -3.0 0.5" xyaxes="1 0 0 0 0 1" />
    <camera name="track" mode="trackcom" pos="0 -3.0 0.5" xyaxes="1 0 0 0 0 1" />
    <body name="root" pos="0 0 0.01" quat="1 0 0 0">
      <freejoint name="root" />
      <site name="imu" size="0.01" pos="0 0 0" />
      <geom type="mesh" rgba="0.796078 0.823529 0.937255 1" mesh="CLS6336_Servo" contype="1" conaffinity="0" density="0" group="1" class="visualgeom" />
      <geom type="mesh" rgba="0.796078 0.823529 0.937255 1" mesh="CLS6336_Servo" />
      <body name="Hip_Horn" pos="0.0253094 0.00109081 0.00986222" quat="0.489117 -0.489117 -0.510651 0.510651">
        <inertial pos="-0.0349472 -0.0349472 -0.0140663" quat="-0.27677 0.638033 0.264282 0.668182" mass="0.0511315" diaginertia="0.000102532 0.000101158 4.51177e-06" />
        <joint name="Revolute_3" pos="0 0 0" axis="0 0 1" limited="false" actuatorfrcrange="-80 80" />
        <geom type="mesh" rgba="0.615686 0.811765 0.929412 1" mesh="Hip_Horn" contype="1" conaffinity="0" density="0" group="1" class="visualgeom" />
        <geom type="mesh" rgba="0.615686 0.811765 0.929412 1" mesh="Hip_Horn" />
        <body name="RHS,_Servo_Cam" pos="0 0 -0.00315" quat="0.707107 0 0 0.707107">
          <inertial pos="-0.00181979 -0.0191473 -0.0015295" quat="0 0.707107 0 0.707107" mass="0.0214782" diaginertia="1.28908e-05 7.75454e-06 5.36417e-06" />
          <joint name="Revolute_4" pos="0 0 0" axis="0 0 1" range="0 6.28319" actuatorfrcrange="-80 80" />
          <geom type="mesh" rgba="0.909804 0.572549 0.164706 1" mesh="RHS,_Servo_Cam" contype="1" conaffinity="0" density="0" group="1" class="visualgeom" />
          <geom type="mesh" rgba="0.909804 0.572549 0.164706 1" mesh="RHS,_Servo_Cam" />
        </body>
        <body name="(RIGHT_Lower_Leg_simple)-(Boss-Extrude3)" pos="-0.0919239 -0.0919239 -0.0132" quat="2.14387e-08 -0.92388 -0.382683 8.88021e-09">
          <inertial pos="0.0449127 -0.0431117 0.00218961" quat="0.671876 0.630225 0.300886 0.246713" mass="0.0576445" diaginertia="0.000157192 0.000156187 5.83259e-06" />
          <joint name="Revolute_5" pos="0 0 0" axis="0 0 1" limited="false" actuatorfrcrange="-80 80" />
          <geom type="mesh" rgba="0.372549 0.654902 0.239216 1" mesh="(RIGHT_Lower_Leg_simple)-(Boss-Extrude3)" contype="1" conaffinity="0" density="0" group="1" class="visualgeom" />
          <geom type="mesh" rgba="0.372549 0.654902 0.239216 1" mesh="(RIGHT_Lower_Leg_simple)-(Boss-Extrude3)" />
          <body name="Push_Rod,_Upper" pos="-0.0282815 0.0238569 -0.00405" quat="-2.32051e-08 1 0 0">
            <inertial pos="0.0651405 0 -0.0020636" quat="0 0.707107 0 0.707107" mass="0.00677755" diaginertia="1.01233e-05 1.00822e-05 1e-06" />
            <joint name="Revolute_6" pos="0 0 0" axis="0 0 1" limited="false" actuatorfrcrange="-80 80" />
            <geom type="mesh" rgba="0.282353 0.54902 0.160784 1" mesh="Push_Rod,_Upper" contype="1" conaffinity="0" density="0" group="1" class="visualgeom" />
            <geom type="mesh" rgba="0.282353 0.54902 0.160784 1" mesh="Push_Rod,_Upper" />
          </body>
        </body>
      </body>
      <body name="Knee_Horn" pos="0.0265581 -0.0278823 -0.0101378" quat="0.0152272 0.706943 0.0152272 -0.706943">
        <inertial pos="0 -0.0103855 -0.00111939" mass="0.00385987" diaginertia="1e-06 1e-06 1e-06" />
        <joint name="Revolute_1" pos="0 0 0" axis="0 0 1" range="0.523599 2.44346" actuatorfrcrange="-80 80" />
        <geom type="mesh" rgba="0.615686 0.811765 0.929412 1" mesh="Knee_Horn" contype="1" conaffinity="0" density="0" group="1" class="visualgeom" />
        <geom type="mesh" rgba="0.615686 0.811765 0.929412 1" mesh="Knee_Horn" />
        <body name="Push_Rod,_Cam" pos="0 -0.035 -0.00705" quat="-2.32051e-08 0 0 1">
          <inertial pos="0.0188243 0 -0.00182735" mass="0.00204623" diaginertia="1e-06 1e-06 1e-06" />
          <joint name="Revolute_2" pos="0 0 0" axis="0 0 1" range="0 6.28319" actuatorfrcrange="-80 80" />
          <geom type="mesh" rgba="0.654902 0.823529 0.576471 1" mesh="Push_Rod,_Cam" contype="1" conaffinity="0" density="0" group="1" class="visualgeom" />
          <geom type="mesh" rgba="0.654902 0.823529 0.576471 1" mesh="Push_Rod,_Cam" />
        </body>
      </body>
    </body>
  </worldbody>

  <equality>
    <joint joint1="Revolute_6" joint2="Revolute_4" polycoef="0 1 0 0 0"/>
    <joint joint1="Revolute_6" joint2="Revolute_4" polycoef="1 0 0 0 0"/>
  </equality>

  <actuator>
    <motor name="Revolute_3" joint="Revolute_3" ctrllimited="true" ctrlrange="-80 80" gear="1" />
    <motor name="Revolute_4" joint="Revolute_4" ctrllimited="true" ctrlrange="-80 80" gear="1" />
    <motor name="Revolute_5" joint="Revolute_5" ctrllimited="true" ctrlrange="-80 80" gear="1" />
    <motor name="Revolute_6" joint="Revolute_6" ctrllimited="true" ctrlrange="-80 80" gear="1" />
    <motor name="Revolute_1" joint="Revolute_1" ctrllimited="true" ctrlrange="-80 80" gear="1" />
    <motor name="Revolute_2" joint="Revolute_2" ctrllimited="true" ctrlrange="-80 80" gear="1" />
  </actuator>

  <sensor>
    <actuatorpos name="Revolute_3_p" actuator="Revolute_3" />
    <actuatorvel name="Revolute_3_v" actuator="Revolute_3" />
    <actuatorfrc name="Revolute_3_f" actuator="Revolute_3" noise="0.001" />
    <actuatorpos name="Revolute_4_p" actuator="Revolute_4" />
    <actuatorvel name="Revolute_4_v" actuator="Revolute_4" />
    <actuatorfrc name="Revolute_4_f" actuator="Revolute_4" noise="0.001" />
    <actuatorpos name="Revolute_5_p" actuator="Revolute_5" />
    <actuatorvel name="Revolute_5_v" actuator="Revolute_5" />
    <actuatorfrc name="Revolute_5_f" actuator="Revolute_5" noise="0.001" />
    <actuatorpos name="Revolute_6_p" actuator="Revolute_6" />
    <actuatorvel name="Revolute_6_v" actuator="Revolute_6" />
    <actuatorfrc name="Revolute_6_f" actuator="Revolute_6" noise="0.001" />
    <actuatorpos name="Revolute_1_p" actuator="Revolute_1" />
    <actuatorvel name="Revolute_1_v" actuator="Revolute_1" />
    <actuatorfrc name="Revolute_1_f" actuator="Revolute_1" noise="0.001" />
    <actuatorpos name="Revolute_2_p" actuator="Revolute_2" />
    <actuatorvel name="Revolute_2_v" actuator="Revolute_2" />
    <actuatorfrc name="Revolute_2_f" actuator="Revolute_2" noise="0.001" />
   <framequat name="orientation" objtype="site" noise="0.001" objname="imu" />
    <gyro name="angular-velocity" site="imu" noise="0.005" cutoff="34.9" />
  </sensor>
</mujoco>