<?xml version="1.0" ?>
<robot name="robot">
  <link name="base">
    <inertial>
      <origin rpy="0 0 0" xyz="0 0 0"/>
      <mass value="0.001"/>
      <inertia ixx="0.000001" ixy="0" ixz="0" iyy="0.000001" iyz="0" izz="0.000001"/>
    </inertial>
  </link>
  <joint name="floating_base" type="fixed">
    <origin rpy="0 0 0" xyz="0 0 0"/>
    <parent link="base"/>
    <child link="Base_part"/>
  </joint>
  <link name="Base_part">
    <visual>
      <origin xyz="0 0 0" rpy="0 0 0"/>
      <geometry>
        <mesh filename="meshes/Base_part.stl"/>
      </geometry>
      <material name="Base_part_material">
        <color rgba="0.61568627 0.81176471 0.92941176 1"/>
      </material>
    </visual>
    <collision>
      <origin xyz="0 0 0" rpy="0 0 0"/>
      <geometry>
        <mesh filename="meshes/Base_part.stl"/>
      </geometry>
    </collision>
    <inertial>
      <mass value="1.9470866"/>
      <inertia ixx="0.0020269624" iyy="0.0020300963" izz="0.0008143818" ixy="0" ixz="0" iyz="-5.8257953e-06"/>
      <origin xyz="0 0 0" rpy="0 0 0"/>
    </inertial>
  </link>
  <joint name="Revolute_1" type="revolute">
    <origin xyz="0 -0.025098952 0.030237485" rpy="1.5707963 0 0"/>
    <parent link="Base_part"/>
    <child link="Propeller_part"/>
    <limit effort="80" velocity="5" lower="0" upper="3.1415927"/>
    <axis xyz="0 0 1"/>
  </joint>
  <link name="Propeller_part">
    <visual>
      <origin xyz="0 0 0" rpy="0 0 0"/>
      <geometry>
        <mesh filename="meshes/Propeller_part.stl"/>
      </geometry>
      <material name="Propeller_part_material">
        <color rgba="0.61568627 0.81176471 0.92941176 1"/>
      </material>
    </visual>
    <collision>
      <origin xyz="0 0 0" rpy="0 0 0"/>
      <geometry>
        <mesh filename="meshes/Propeller_part.stl"/>
      </geometry>
    </collision>
    <inertial>
      <mass value="0.010162016"/>
      <inertia ixx="1e-06" iyy="1e-06" izz="1e-06" ixy="0" ixz="0" iyz="0"/>
      <origin xyz="0 0 0.0025" rpy="0 0 0"/>
    </inertial>
  </link>
</robot>
