<mujoco model="robot">
  <option iterations="50" timestep="0.001" solver="PGS" gravity="0 0 -9.81" />

  <compiler angle="radian" meshdir="meshes" eulerseq="zyx" autolimits="true" />

  <default>
    <joint limited="true" damping="0.01" armature="0.01" frictionloss="0.01" />
    <geom condim="4" contype="1" conaffinity="15" friction="0.9 0.2 0.2" solref="0.001 2" />
    <motor ctrllimited="true" />
    <equality solref="0.001 2" />
    <default class="visualgeom">
      <geom material="visualgeom" condim="1" contype="0" conaffinity="0" />
    </default>
  </default>

  <asset>
    <mesh name="Base_part" file="Base_part.stl" />
    <mesh name="Propeller_part" file="Propeller_part.stl" />
    <texture name="texplane" type="2d" builtin="checker" rgb1=".0 .0 .0" rgb2=".8 .8 .8" width="100" height="100" />
    <material name="matplane" reflectance="0." texture="texplane" texrepeat="1 1" texuniform="true" />
    <material name="visualgeom" rgba="0.5 0.9 0.2 1" />
  </asset>

  <worldbody>
    <light directional="true" diffuse="0.4 0.4 0.4" specular="0.1 0.1 0.1" pos="0 0 5.0" dir="0 0 -1" castshadow="false" />
    <light directional="true" diffuse="0.6 0.6 0.6" specular="0.2 0.2 0.2" pos="0 0 4" dir="0 0 -1" />
    <geom name="ground" type="plane" pos="0 0 0" size="100 100 0.001" quat="1 0 0 0" material="matplane" condim="3" conaffinity="15" />
    <camera name="fixed" pos="0 -3.0 0.5" xyaxes="1 0 0 0 0 1" />
    <camera name="track" mode="trackcom" pos="0 -3.0 0.5" xyaxes="1 0 0 0 0 1" />
    <body name="root" pos="0 0 0.01" quat="1 0 0 0">
      <freejoint name="root" />
      <site name="imu" size="0.01" pos="0 0 0" />
      <geom type="mesh" rgba="0.615686 0.811765 0.929412 1" mesh="Base_part" contype="1" conaffinity="0" density="0" group="1" class="visualgeom" />
      <geom type="mesh" rgba="0.615686 0.811765 0.929412 1" mesh="Base_part" />
      <body name="Propeller_part" pos="0 -0.025099 0.0302375" quat="0.707107 0.707107 0 0">
        <inertial pos="0 0 0.0025" mass="0.010162" diaginertia="1e-06 1e-06 1e-06" />
        <joint name="Revolute_1" pos="0 0 0" axis="0 0 1" range="0 3.14159" actuatorfrcrange="-80 80" />
        <geom type="mesh" rgba="0.615686 0.811765 0.929412 1" mesh="Propeller_part" contype="1" conaffinity="0" density="0" group="1" class="visualgeom" />
        <geom type="mesh" rgba="0.615686 0.811765 0.929412 1" mesh="Propeller_part" />
      </body>
    </body>
  </worldbody>

  <actuator>
    <motor name="Revolute_1" joint="Revolute_1" ctrllimited="true" ctrlrange="-80 80" gear="1" />
  </actuator>

  <sensor>
    <actuatorpos name="Revolute_1_p" actuator="Revolute_1" />
    <actuatorvel name="Revolute_1_v" actuator="Revolute_1" />
    <actuatorfrc name="Revolute_1_f" actuator="Revolute_1" noise="0.001" />
    <framequat name="orientation" objtype="site" noise="0.001" objname="imu" />
    <gyro name="angular-velocity" site="imu" noise="0.005" cutoff="34.9" />
  </sensor>
</mujoco>