<mujoco model="urdf_robot">
  <option iterations="50" timestep="0.001" solver="PGS" gravity="0 0 -9.81" />

  <compiler angle="radian" meshdir="meshes" eulerseq="zyx" autolimits="true" />

  <default>
    <joint limited="true" damping="0.01" armature="0.01" frictionloss="0.01" />
    <geom condim="4" contype="1" conaffinity="15" friction="0.9 0.2 0.2" solref="0.001 2" />
    <motor ctrllimited="true" />
    <equality solref="0.001 2" />
    <default class="visualgeom">
      <geom material="visualgeom" condim="1" contype="0" conaffinity="0" />
    </default>
  </default>

  <asset>
    <mesh name="Torso_-_Middle_Section_p1" file="Torso_-_Middle_Section_p1.stl" />
    <mesh name="LHS,_FRONT" file="LHS,_FRONT.stl" />
    <mesh name="RHS,_FRONT" file="RHS,_FRONT.stl" />
    <mesh name="Rear_Right_Servo_Box" file="Rear_Right_Servo_Box.stl" />
    <mesh name="LHS,_REAR" file="LHS,_REAR.stl" />
    <mesh name="Hip_Horn" file="Hip_Horn.stl" />
    <mesh name="Hip_Horn_2" file="Hip_Horn_2.stl" />
    <mesh name="Hip_Horn_3" file="Hip_Horn_3.stl" />
    <mesh name="Hip_Horn_4" file="Hip_Horn_4.stl" />
    <mesh name="LEFT_Lower_Leg" file="LEFT_Lower_Leg.stl" />
    <mesh name="RIGHT_Lower_Leg" file="RIGHT_Lower_Leg.stl" />
    <mesh name="RIGHT_Lower_Leg_2" file="RIGHT_Lower_Leg_2.stl" />
    <mesh name="LEFT_Lower_Leg_2" file="LEFT_Lower_Leg_2.stl" />
    <texture name="texplane" type="2d" builtin="checker" rgb1=".0 .0 .0" rgb2=".8 .8 .8" width="100" height="100" />
    <material name="matplane" reflectance="0." texture="texplane" texrepeat="1 1" texuniform="true" />
    <material name="visualgeom" rgba="0.5 0.9 0.2 1" />
  </asset>

  <worldbody>
    <camera name="fixed" pos="0 -3.0 0.5" xyaxes="1 0 0 0 0 1" />
    <camera name="track" mode="trackcom" pos="0 -3.0 0.5" xyaxes="1 0 0 0 0 1" />
    <body name="root" pos="0 0 0.01" quat="1 0 0 0">
      <freejoint name="root" />
      <site name="imu" size="0.01" pos="0 0 0" />
      <geom type="mesh" rgba="0.682353 0.333333 0.737255 1" mesh="Torso_-_Middle_Section_p1" contype="1" conaffinity="0" density="0" group="1" class="visualgeom" />
      <geom type="mesh" rgba="0.682353 0.333333 0.737255 1" mesh="Torso_-_Middle_Section_p1" />
      <body name="LHS,_FRONT" pos="0.0528396 -0.0797826 0.00621881" quat="0.707107 -0.707107 2.28709e-08 -1.50228e-08">
        <inertial pos="3.00389e-07 -0.00707888 -0.0385084" quat="0.501247 0.498509 0.513412 0.486465" mass="0.553078" diaginertia="0.000232539 0.0002139 0.000171814" />
        <joint name="dof_shoulder_front_left" pos="0 0 0" axis="0 0 1" range="0 3.14159" actuatorfrcrange="-80 80" />
        <geom type="mesh" rgba="0.972549 0.529412 0.00392157 1" mesh="LHS,_FRONT" contype="1" conaffinity="0" density="0" group="1" class="visualgeom" />
        <geom type="mesh" rgba="0.972549 0.529412 0.00392157 1" mesh="LHS,_FRONT" />
        <body name="Hip_Horn" pos="-0.0145 -0.03185 -0.02865" quat="0.5 -0.5 -0.5 -0.5">
          <inertial pos="0.0349472 0.0349472 -0.0140663" quat="-0.264282 0.668182 0.27677 0.638033" mass="0.0511315" diaginertia="0.000102532 0.000101158 4.51177e-06" />
          <joint name="dof_hip_front_left" pos="0 0 0" axis="0 0 1" range="0 3.14159" actuatorfrcrange="-80 80" />
          <geom type="mesh" rgba="0.615686 0.811765 0.929412 1" mesh="Hip_Horn" contype="1" conaffinity="0" density="0" group="1" class="visualgeom" />
          <geom type="mesh" rgba="0.615686 0.811765 0.929412 1" mesh="Hip_Horn" />
          <body name="LEFT_Lower_Leg" pos="0.0919239 0.0919239 -0.0132" quat="8.88021e-09 -0.382683 0.92388 -2.14387e-08">
            <inertial pos="0.0521679 0.0503249 -0.00061848" quat="-0.26416 0.623178 0.267705 0.685713" mass="0.0455909" diaginertia="0.000128574 0.000127512 2.91333e-06" />
            <joint name="dof_knee_front_left" pos="0 0 0" axis="0 0 1" range="0 1.91986" actuatorfrcrange="-80 80" />
            <geom type="mesh" rgba="0.372549 0.654902 0.239216 1" mesh="LEFT_Lower_Leg" contype="1" conaffinity="0" density="0" group="1" class="visualgeom" />
            <geom type="mesh" rgba="0.372549 0.654902 0.239216 1" mesh="LEFT_Lower_Leg" />
          </body>
        </body>
      </body>
      <body name="RHS,_FRONT" pos="-0.0526604 -0.0797826 0.00621881" quat="4.18177e-08 -3.92402e-09 0.707107 0.707107">
        <inertial pos="-3.37274e-07 -0.0070789 -0.0385084" quat="0.513408 0.486468 0.501245 0.498513" mass="0.553077" diaginertia="0.000232538 0.000213899 0.000171813" />
        <joint name="dof_shoulder_front_right" pos="0 0 0" axis="0 0 1" range="0 3.14159" actuatorfrcrange="-80 80" />
        <geom type="mesh" rgba="0.972549 0.529412 0.00392157 1" mesh="RHS,_FRONT" contype="1" conaffinity="0" density="0" group="1" class="visualgeom" />
        <geom type="mesh" rgba="0.972549 0.529412 0.00392157 1" mesh="RHS,_FRONT" />
        <body name="Hip_Horn_2" pos="0.0145 -0.03185 -0.02865" quat="0.707107 -0.707107 0 -3.2817e-08">
          <inertial pos="-0.0349472 -0.0349472 -0.0140663" quat="-0.27677 0.638033 0.264282 0.668182" mass="0.0511315" diaginertia="0.000102532 0.000101158 4.51177e-06" />
          <joint name="dof_hip_front_right" pos="0 0 0" axis="0 0 1" range="0 3.14159" actuatorfrcrange="-80 80" />
          <geom type="mesh" rgba="0.615686 0.811765 0.929412 1" mesh="Hip_Horn_2" contype="1" conaffinity="0" density="0" group="1" class="visualgeom" />
          <geom type="mesh" rgba="0.615686 0.811765 0.929412 1" mesh="Hip_Horn_2" />
          <body name="RIGHT_Lower_Leg" pos="-0.0919239 -0.0919239 -0.0132" quat="8.88021e-09 -0.382683 0.92388 -2.14387e-08">
            <inertial pos="0.0521679 -0.0503249 -0.000618479" quat="0.26416 0.623178 -0.267705 0.685713" mass="0.0455909" diaginertia="0.000128574 0.000127512 2.91333e-06" />
            <joint name="dof_knee_front_right" pos="0 0 0" axis="0 0 1" range="1.22173 3.14159" actuatorfrcrange="-80 80" />
            <geom type="mesh" rgba="0.372549 0.654902 0.239216 1" mesh="RIGHT_Lower_Leg" contype="1" conaffinity="0" density="0" group="1" class="visualgeom" />
            <geom type="mesh" rgba="0.372549 0.654902 0.239216 1" mesh="RIGHT_Lower_Leg" />
          </body>
        </body>
      </body>
      <body name="Rear_Right_Servo_Box" pos="-0.0526604 0.0798174 0.00621881" quat="0.707107 0.707107 3.92402e-09 -3.92402e-09">
        <inertial pos="-3.32755e-07 0.0070789 -0.0385085" quat="0.486475 0.513421 0.498507 0.50123" mass="0.553077" diaginertia="0.000232538 0.000213899 0.000171813" />
        <joint name="dof_shoulder_rear_right" pos="0 0 0" axis="0 0 1" range="0 3.14159" actuatorfrcrange="-80 80" />
        <geom type="mesh" rgba="0.972549 0.529412 0.00392157 1" mesh="Rear_Right_Servo_Box" contype="1" conaffinity="0" density="0" group="1" class="visualgeom" />
        <geom type="mesh" rgba="0.972549 0.529412 0.00392157 1" mesh="Rear_Right_Servo_Box" />
        <body name="Hip_Horn_3" pos="0.0145 0.03185 -0.04865" quat="0.5 0.5 -0.5 0.5">
          <inertial pos="0.0349472 0.0349472 -0.0140663" quat="-0.264282 0.668182 0.27677 0.638033" mass="0.0511315" diaginertia="0.000102532 0.000101158 4.51177e-06" />
          <joint name="dof_hip_rear_right" pos="0 0 0" axis="0 0 1" range="0 3.14159" actuatorfrcrange="-80 80" />
          <geom type="mesh" rgba="0.615686 0.811765 0.929412 1" mesh="Hip_Horn_3" contype="1" conaffinity="0" density="0" group="1" class="visualgeom" />
          <geom type="mesh" rgba="0.615686 0.811765 0.929412 1" mesh="Hip_Horn_3" />
          <body name="RIGHT_Lower_Leg_2" pos="0.0919239 0.0919239 -0.0132" quat="2.14387e-08 -0.92388 -0.382683 8.88021e-09">
            <inertial pos="0.0521679 -0.0503249 -0.000618479" quat="0.26416 0.623178 -0.267705 0.685713" mass="0.0455909" diaginertia="0.000128574 0.000127512 2.91333e-06" />
            <joint name="dof_knee_rear_right" pos="0 0 0" axis="0 0 1" range="1.22173 3.14159" actuatorfrcrange="-80 80" />
            <geom type="mesh" rgba="0.372549 0.654902 0.239216 1" mesh="RIGHT_Lower_Leg_2" contype="1" conaffinity="0" density="0" group="1" class="visualgeom" />
            <geom type="mesh" rgba="0.372549 0.654902 0.239216 1" mesh="RIGHT_Lower_Leg_2" />
          </body>
        </body>
      </body>
      <body name="LHS,_REAR" pos="0.0528396 0.0798174 0.00621881" quat="-2.28709e-08 -2.28709e-08 -0.707107 0.707107">
        <inertial pos="3.36557e-07 0.0070789 -0.0385084" quat="0.498505 0.501232 0.486474 0.513423" mass="0.553077" diaginertia="0.000232538 0.000213899 0.000171813" />
        <joint name="dof_shoulder_rear_left" pos="0 0 0" axis="0 0 1" range="0 3.14159" actuatorfrcrange="-80 80" />
        <geom type="mesh" rgba="0.972549 0.529412 0.00392157 1" mesh="LHS,_REAR" contype="1" conaffinity="0" density="0" group="1" class="visualgeom" />
        <geom type="mesh" rgba="0.972549 0.529412 0.00392157 1" mesh="LHS,_REAR" />
        <body name="Hip_Horn_4" pos="-0.0145 0.03185 -0.04865" quat="0.707107 0.707107 3.2817e-08 0">
          <inertial pos="0.0349472 -0.0349472 -0.0140663" quat="0.264282 0.668182 -0.27677 0.638033" mass="0.0511315" diaginertia="0.000102532 0.000101158 4.51177e-06" />
          <joint name="dof_hip_rear_left" pos="0 0 0" axis="0 0 1" range="0 3.14159" actuatorfrcrange="-80 80" />
          <geom type="mesh" rgba="0.615686 0.811765 0.929412 1" mesh="Hip_Horn_4" contype="1" conaffinity="0" density="0" group="1" class="visualgeom" />
          <geom type="mesh" rgba="0.615686 0.811765 0.929412 1" mesh="Hip_Horn_4" />
          <body name="LEFT_Lower_Leg_2" pos="0.0919239 -0.0919239 -0.0132" quat="8.88021e-09 -0.382683 -0.92388 2.14387e-08">
            <inertial pos="0.0521679 0.0503249 -0.00061848" quat="-0.26416 0.623178 0.267705 0.685713" mass="0.0455909" diaginertia="0.000128574 0.000127512 2.91333e-06" />
            <joint name="dof_knee_rear_left" pos="0 0 0" axis="0 0 1" range="0 1.91986" actuatorfrcrange="-80 80" />
            <geom type="mesh" rgba="0.372549 0.654902 0.239216 1" mesh="LEFT_Lower_Leg_2" contype="1" conaffinity="0" density="0" group="1" class="visualgeom" />
            <geom type="mesh" rgba="0.372549 0.654902 0.239216 1" mesh="LEFT_Lower_Leg_2" />
          </body>
        </body>
      </body>
    </body>
  </worldbody>

  <actuator>
    <position name="dof_shoulder_front_left" joint="dof_shoulder_front_left" kp="100" ctrlrange="0 3.14159" />
    <position name="dof_hip_front_left" joint="dof_hip_front_left" kp="100" ctrlrange="0 3.14159" />
    <position name="dof_knee_front_left" joint="dof_knee_front_left" kp="100" ctrlrange="0 1.91986" />
    <position name="dof_shoulder_front_right" joint="dof_shoulder_front_right" kp="100" ctrlrange="0 3.14159" />
    <position name="dof_hip_front_right" joint="dof_hip_front_right" kp="100" ctrlrange="0 3.14159" />
    <position name="dof_knee_front_right" joint="dof_knee_front_right" kp="100" ctrlrange="1.22173 3.14159" />
    <position name="dof_shoulder_rear_right" joint="dof_shoulder_rear_right" kp="100" ctrlrange="0 3.14159" />
    <position name="dof_hip_rear_right" joint="dof_hip_rear_right" kp="100" ctrlrange="0 3.14159" />
    <position name="dof_knee_rear_right" joint="dof_knee_rear_right" kp="100" ctrlrange="1.22173 3.14159" />
    <position name="dof_shoulder_rear_left" joint="dof_shoulder_rear_left" kp="100" ctrlrange="0 3.14159" />
    <position name="dof_hip_rear_left" joint="dof_hip_rear_left" kp="100" ctrlrange="0 3.14159" />
    <position name="dof_knee_rear_left" joint="dof_knee_rear_left" kp="100" ctrlrange="0 1.91986" />
  </actuator>

  <sensor>
    <!-- Joint Position Sensors -->
    <jointpos name="shoulder_front_left" joint="dof_shoulder_front_left" />
    <jointpos name="hip_front_left" joint="dof_hip_front_left" />
    <jointpos name="knee_front_left" joint="dof_knee_front_left" />
    <jointpos name="shoulder_front_right" joint="dof_shoulder_front_right" />
    <jointpos name="hip_front_right" joint="dof_hip_front_right" />
    <jointpos name="knee_front_right" joint="dof_knee_front_right" />
    <jointpos name="shoulder_rear_right" joint="dof_shoulder_rear_right" />
    <jointpos name="hip_rear_right" joint="dof_hip_rear_right" />
    <jointpos name="knee_rear_right" joint="dof_knee_rear_right" />
    <jointpos name="shoulder_rear_left" joint="dof_shoulder_rear_left" />
    <jointpos name="hip_rear_left" joint="dof_hip_rear_left" />
    <jointpos name="knee_rear_left" joint="dof_knee_rear_left" />

    <!-- Joint Velocity Sensors -->
    <jointvel name="shoulder_front_left_vel" joint="dof_shoulder_front_left" />
    <jointvel name="hip_front_left_vel" joint="dof_hip_front_left" />
    <jointvel name="knee_front_left_vel" joint="dof_knee_front_left" />
    <jointvel name="shoulder_front_right_vel" joint="dof_shoulder_front_right" />
    <jointvel name="hip_front_right_vel" joint="dof_hip_front_right" />
    <jointvel name="knee_front_right_vel" joint="dof_knee_front_right" />
    <jointvel name="shoulder_rear_right_vel" joint="dof_shoulder_rear_right" />
    <jointvel name="hip_rear_right_vel" joint="dof_hip_rear_right" />
    <jointvel name="knee_rear_right_vel" joint="dof_knee_rear_right" />
    <jointvel name="shoulder_rear_left_vel" joint="dof_shoulder_rear_left" />
    <jointvel name="hip_rear_left_vel" joint="dof_hip_rear_left" />
    <jointvel name="knee_rear_left_vel" joint="dof_knee_rear_left" />

    <!-- IMU Sensors (if you need orientation/angular velocity) -->
    <framequat name="orientation" objtype="site" objname="imu" />
    <gyro name="angular-velocity" site="imu" />
  </sensor>
</mujoco>